Workbook

Sheet 사용법
A1: 문서다움 1.6 — 5단계 사내 검증 점검표
A2: 작성 2026-10-20 · 대상 파일: 문서다움_v1.6.html (SHA-256 cb55e7e410d5af0b11f7b7c1c3ec2c4ba3f1edfd35425dd64067ee214c5d1ffe)
A4: 작성 방법
A5: 1. [3_시험문서]의 목록대로 문서를 준비하고 "준비 수량"에 실제 수량을 적습니다. DRM 문서는 사내 승인 절차로 해제한 사본만 씁니다(D18은 경고 확인용으로만 사용).
A6: 2. [0_시험환경]에 시험 PC·브라우저 정보를 적습니다. PC가 여러 대면 줄을 추가합니다.
A7: 3. [1_환경점검] → [2_기능점검] 순서로 시험하고, Edge 결과·Chrome 결과 칸에서 통과/실패/보류/해당없음을 고릅니다.
A8: 4. 실패나 보류가 나오면 [4_오류기록]에 한 줄씩 적고, 그 오류번호(예: ER-001)를 점검표 "비고·오류번호" 칸에 적습니다. 화면 캡처는 오류번호를 파일명으로 저장합니다.
A9: 5. [요약] 시트에서 진행률과 판정을 확인합니다. 판정은 자동 계산됩니다.
A11: 칸 색깔
A12: 노란 칸 = 시험하는 사람이 입력하는 칸입니다. 나머지 칸은 수정하지 않습니다.
A13: "치명" Y = 하나라도 실패하면 배포할 수 없는 항목입니다. 표시가 없는 항목은 실패해도 안내문 보완 등으로 배포를 검토할 수 있습니다.
A15: 결과 값의 뜻
... A19: 시험이 끝나면 이 파일과 [4_오류기록]의 캡처를 Claude와의 대화에 첨부해 주세요. 원인 분석과 수정판(1.7) 제작은 그 자료로 진행합니다. 회사 문서 원본은 첨부하지 말고, 문제가 된 문서의 특징(쪽수·형식·작성 프로그램 등)만 적어 주세요.

Sheet 요약
A1: 5단계 사내 검증 요약
A2: 모든 값은 각 시트 입력값으로 자동 계산됩니다. 이 시트는 입력하지 않습니다.
A4: 구분 | B4: 브라우저 | C4: 전체 항목 | D4: 통과 | E4: 실패 | F4: 보류 | G4: 해당없음 | H4: 미실시 | I4: 진행률 | J4: 치명 항목 실패 | K4: 치명 항목 미실시
A5: 1_환경점검 | B5: Edge | C5: =SUMPRODUCT((LEN(1_환경점검!A5:A32)=3)*ISNUMBER(--MID(1_환경점검!A5:A32,2,2))) -> 23 | D5: =COUNTIF(1_환경점검!H5:H32,"통과") -> 0 | E5: =COUNTIF(1_환경점검!H5:H32,"실패") -> 0 | F5: =COUNTIF(1_환경점검!H5:H32,"보류") -> 0 | G5: =COUNTIF(1_환경점검!H5:H32,"해당없음") -> 0 | H5: =C5-D5-E5-F5-G5 -> 23 | I5: =IF(C5=0,0,(C5-H5)/C5) -> 0 | J5: =COUNTIFS(1_환경점검!G5:G32,"Y",1_환경점검!H5:H32,"실패") -> 0 | K5: =SUMPRODUCT((1_환경점검!G5:G32="Y")*(1_환경점검!H5:H32="")) -> 10
A6: 1_환경점검 | B6: Chrome | C6: =SUMPRODUCT((LEN(1_환경점검!A5:A32)=3)*ISNUMBER(--MID(1_환경점검!A5:A32,2,2))) -> 23 | D6: =COUNTIF(1_환경점검!I5:I32,"통과") -> 0 | E6: =COUNTIF(1_환경점검!I5:I32,"실패") -> 0 | F6: =COUNTIF(1_환경점검!I5:I32,"보류") -> 0 | G6: =COUNTIF(1_환경점검!I5:I32,"해당없음") -> 0 | H6: =C6-D6-E6-F6-G6 -> 23 | I6: =IF(C6=0,0,(C6-H6)/C6) -> 0 | J6: =COUNTIFS(1_환경점검!G5:G32,"Y",1_환경점검!I5:I32,"실패") -> 0 | K6: =SUMPRODUCT((1_환경점검!G5:G32="Y")*(1_환경점검!I5:I32="")) -> 10
A7: 2_기능점검 | B7: Edge | C7: =SUMPRODUCT((LEN(2_기능점검!A5:A56)=3)*ISNUMBER(--MID(2_기능점검!A5:A56,2,2))) -> 46 | D7: =COUNTIF(2_기능점검!H5:H56,"통과") -> 0 | E7: =COUNTIF(2_기능점검!H5:H56,"실패") -> 0 | F7: =COUNTIF(2_기능점검!H5:H56,"보류") -> 0 | G7: =COUNTIF(2_기능점검!H5:H56,"해당없음") -> 0 | H7: =C7-D7-E7-F7-G7 -> 46 | I7: =IF(C7=0,0,(C7-H7)/C7) -> 0 | J7: =COUNTIFS(2_기능점검!G5:G56,"Y",2_기능점검!H5:H56,"실패") -> 0 | K7: =SUMPRODUCT((2_기능점검!G5:G56="Y")*(2_기능점검!H5:H56="")) -> 11
A8: 2_기능점검 | B8: Chrome | C8: =SUMPRODUCT((LEN(2_기능점검!A5:A56)=3)*ISNUMBER(--MID(2_기능점검!A5:A56,2,2))) -> 46 | D8: =COUNTIF(2_기능점검!I5:I56,"통과") -> 0 | E8: =COUNTIF(2_기능점검!I5:I56,"실패") -> 0 | F8: =COUNTIF(2_기능점검!I5:I56,"보류") -> 0 | G8: =COUNTIF(2_기능점검!I5:I56,"해당없음") -> 0 | H8: =C8-D8-E8-F8-G8 -> 46 | I8: =IF(C8=0,0,(C8-H8)/C8) -> 0 | J8: =COUNTIFS(2_기능점검!G5:G56,"Y",2_기능점검!I5:I56,"실패") -> 0 | K8: =SUMPRODUCT((2_기능점검!G5:G56="Y")*(2_기능점검!I5:I56="")) -> 11
A9: 합계 | C9: =SUM(C5:C8) -> 138 | D9: =SUM(D5:D8) -> 0 | E9: =SUM(E5:E8) -> 0 | F9: =SUM(F5:F8) -> 0 | G9: =SUM(G5:G8) -> 0 | H9: =SUM(H5:H8) -> 138 | I9: =IF(C9=0,0,(C9-H9)/C9) -> 0 | J9: =SUM(J5:J8) -> 0 | K9: =SUM(K5:K8) -> 42
A11: 시험 문서 준비 | C11: =3_시험문서!E29 -> 0 | D11: ="/ 목표 "&3_시험문서!D29&"건" -> / 목표 112건
A12: 오류 기록 건수 | C12: =COUNTA(4_오류기록!A6:A40) -> 0
A14: 판정 | C14: =IF(AND(J9=0,K9=0),"배포 승인 검토 가능 — 치명 항목 전부 통과",IF(J9>0,"보완 필요 — 치명 항목 실패 "&J9&"건","시험 진행 중 — 치명 항목 미실시 "&K9&"건")) -> 시험 진행 중 — 치명 항목 미실시 42건
C15: 치명 항목이 모두 통과해도 실패·보류 항목은 Claude에게 전달해 수정판 반영 여부를 판단합니다. 최종 배포는 회사 승인 절차를 따릅니다.

Sheet 0_시험환경
A1: 시험 환경 기록
A2: 시험에 쓴 PC마다 한 줄씩 적습니다. 첫 줄은 작성 예시이므로 실제 시험 후 지우거나 덮어쓰세요.
A4: PC 구분 | B4: 시험자 | C4: 시험일 | D4: OS(버전) | E4: CPU | F4: 메모리(GB) | G4: Edge 버전 | H4: Chrome 버전 | I4: 보안 프로그램(V3·DRM 등) | J4: 인터넷 차단 여부 | K4: 비고
A5: 예시) 일반 사무용 | B5: 홍길동 | C5: 2026-10-27 | D5: Windows 11 23H2 | E5: Intel i5-8500 | F5: 8 | G5: 130.0.xxxx | H5: 130.0.xxxx | I5: V3, OO DRM 에이전트 | J5: 차단(내부망) | K5: 엣지 기본 브라우저

Sheet 1_환경점검
A1: 1. 환경·보안 점검 (Edge·Chrome 모두)
A2: 회사 PC·브라우저·보안 프로그램에서 프로그램 자체가 정상 동작하는지 확인합니다. 기능 점검보다 먼저 합니다.
A4: ID | B4: 영역 | C4: 점검 항목 | D4: 시험 방법 | E4: 사용 문서(3_시험문서 ID) | F4: 기대 결과(통과 기준) | G4: 치명 | H4: Edge 결과 | I4: Chrome 결과 | J4: 처리시간(초) | K4: 비고·오류번호
A5: 실행·배포
A6: E01 | B6: 최초 실행 | C6: 인터넷 없이 첫 실행 | D6: 인터넷이 차단된 내부망 PC에 HTML만 복사하고, 브라우저 캐시를 지운 뒤 더블클릭(또는 브라우저로 끌어다 놓기)으로 엽니다. | E6: - | F6: 화면이 3~10초 안에 뜨고 아이콘 42개가 보입니다. 오류 창이나 빈 화면이 없습니다. | G6: Y
A7: E02 | B7: 최초 실행 | C7: 버전·해시 확인 | D7: 좌측 하단 "버전 1.6"을 확인하고, 배포 담당자가 파일 해시를 확인합니다(명령: certutil -hashfile 파일명 SHA256). | E7: - | F7: 버전 1.6, 해시가 [사용법]에 적힌 값과 같습니다. | G7: Y
A8: E03 | B8: 최초 실행 | C8: 라이선스 고지 열기 | D8: 화면의 [라이선스] 버튼을 눌러 고지문을 열고 [다운로드]로 TXT를 받아 봅니다. | E8: - | F8: 고지문이 열리고 TXT로 저장됩니다. "문서다움 1.6"과 1.6 변경 내역이 보입니다.
A9: E04 | B9: 최초 실행 | C9: 외부 연결 없음(선택) | D9: F12 개발자 도구 → [네트워크] 탭을 연 채로 PDF 나누기 1건을 실행합니다. 보안 담당 확인용입니다. | E9: D01 | F9: 외부 주소(http/https) 요청이 0건입니다. blob: 항목만 보이는 것은 정상입니다.
A10: E05 | B10: 최초 실행 | C10: 저사양 PC 실행 | D10: 메모리 8GB 이하 PC에서 E01과 OCR 1건(D22)을 실행합니다. | E10: D22 | F10: 멈춤이나 "메모리 부족" 없이 완료됩니다. 처리시간을 적습니다.
A11: 다운로드
A12: E06 | B12: 다운로드 | C12: 결과 1개 다운로드 | D12: PDF 나누기 결과 중 1개의 [다운로드]를 누릅니다. | E12: D01 | F12: 다운로드 폴더에 파일이 저장되고, 해당 결과에 "받음" 표시가 생깁니다. | G12: Y
A13: E07 | B13: 다운로드 | C13: 여러 개 연속 다운로드 | D13: 결과가 여러 개일 때 [다운로드]를 3개 이상 연달아 누릅니다. | E13: D01 | F13: 모두 저장됩니다. "여러 파일 다운로드 허용" 창이 뜨면 비고에 적습니다(정책에 따라 다름).
A14: E08 | B14: 다운로드 | C14: ZIP 일괄 받기 | D14: [모든 결과 ZIP으로 받기]를 누르고, 받은 ZIP을 윈도우 탐색기로 풀어 봅니다. | E14: D01 | F14: ZIP이 저장되고 풀었을 때 결과 수와 파일 수가 같으며 한글 파일명이 깨지지 않습니다. | G14: Y
A15: E09 | B15: 다운로드 | C15: 보안 프로그램 검사 | D15: 받은 PDF·ZIP을 열 때 V3·DRM 에이전트가 차단·자동 암호화하는지 봅니다. | E15: D01 | F15: 차단되지 않습니다. DRM 자동 적용 여부는 결과와 무관하게 비고에 적습니다. | G15: Y
A16: 받지 않은 결과 보호(1.6)
A17: E10 | B17: 결과 보호 | C17: 다른 기능으로 이동 시 경고 | D17: 결과를 받지 않은 상태에서 다른 아이콘을 누릅니다. 창이 뜨면 [취소]를 누릅니다. | E17: D01 | F17: 확인 창이 뜨고, 취소하면 현재 기능과 결과가 그대로 남습니다. | G17: Y
A18: E11 | B18: 결과 보호 | C18: 받고 계속 | D18: E10 창에서 [모두 ZIP으로 받고 계속]을 누릅니다. | E18: D01 | F18: ZIP이 저장된 뒤 다른 기능으로 넘어갑니다.
A19: E12 | B19: 결과 보호 | C19: 받지 않고 계속 | D19: 결과를 다시 만든 뒤 [닫기] → [받지 않고 계속]을 누릅니다. | E19: D01 | F19: 결과가 지워지고 작업 화면이 닫힙니다.
A20: E13 | B20: 결과 보호 | C20: 창·탭 닫기 경고 | D20: 결과를 받지 않은 채 브라우저 탭의 X를 누르거나 F5(새로고침)를 누릅니다. | E20: D01 | F20: "사이트에서 나가시겠습니까?" 같은 브라우저 경고가 뜹니다. | G20: Y
A21: E14 | B21: 결과 보호 | C21: 모두 받은 뒤 경고 없음 | D21: 결과를 모두 받은 뒤 다른 기능으로 이동하고 탭을 닫습니다. | E21: D01 | F21: 확인 창이나 경고 없이 바로 이동·종료됩니다.
A22: 보안정책·진단
A23: E15 | B23: 보안정책 | C23: DRM 파일 경고 | D23: DRM이 걸린 원본을 파일 추가합니다(보안 담당 허락 시, 내용은 열리지 않음). | E23: D18 | F23: "문서보안(DRM) 적용 파일로 보입니다" 경고가 뜨고 목록에서 빠집니다. 표식을 못 찾은 제품은 비고에 제품명을 적습니다. | G23: Y
A24: E16 | B24: 보안정책 | C24: 암호 문서 경고 | D24: 암호가 걸린 Office·한글 문서를 추가합니다. | E24: D19 | F24: 암호·DRM 경고가 뜨고 목록에서 빠집니다. | G24: Y
A25: E17 | B25: 보안정책 | C25: 형식 위장 파일 | D25: 확장자만 바꾼 파일(예: 사진 파일 이름을 .pdf로 바꾼 것)을 추가합니다. | E25: D20 | F25: "확장자와 실제 형식이 다름" 경고가 뜨고 목록에서 빠집니다.
A26: E18 | B26: 보안정책 | C26: 저장소 미사용 | D26: 작업 후 브라우저를 완전히 닫았다가 HTML을 다시 엽니다. | E26: D01 | F26: 이전 파일·결과·암호가 남아 있지 않습니다. | G26: Y
A27: 처리 한도·오류
A28: E19 | B28: 처리 한도 | C28: 대용량 PDF | D28: 300쪽 이상 PDF로 PDF 나누기(50쪽 단위)를 실행합니다. | E28: D04 | F28: 완료되거나, 한도(파일당 500쪽) 초과 시 알아듣기 쉬운 안내가 뜹니다. 처리시간을 적습니다.
A29: E20 | B29: 처리 한도 | C29: 파일 100개 초과 | D29: 파일 101개를 한 번에 추가합니다. | E29: D01 등 | F29: "한 번에 100파일" 안내가 뜨고 초과분이 추가되지 않습니다.
A30: E21 | B30: 오류 처리 | C30: 손상 파일 | D30: 중간이 잘린 PDF를 PDF 텍스트 추출에 넣습니다. | E30: D23 | F30: 해당 파일만 오류로 표시되고 다른 파일은 정상 처리됩니다.
A31: E22 | B31: 오류 처리 | C31: 작업 중단 | D31: 큰 파일 처리 중 [중단]을 누릅니다. | E31: D04 | F31: 처리가 멈추고 이미 끝난 결과는 받을 수 있습니다.
A32: E23 | B32: 오류 처리 | C32: 긴 한글·특수문자 파일명 | D32: 특수문자(괄호·&·#)와 긴 한글 이름의 파일을 변환합니다. | E32: D24 | F32: 결과 파일명이 깨지지 않고 저장됩니다.

Sheet 2_기능점검
A1: 2. 기능 점검 (41개 도구 + 안내·레시피)
A2: 각 기능의 결과물을 원본과 대조합니다. 금액·날짜·표·도장·쪽 순서는 반드시 눈으로 확인합니다.
A4: ID | B4: 영역 | C4: 점검 항목 | D4: 시험 방법 | E4: 사용 문서(3_시험문서 ID) | F4: 기대 결과(통과 기준) | G4: 치명 | H4: Edge 결과 | I4: Chrome 결과 | J4: 처리시간(초) | K4: 비고·오류번호
A5: PDF 도구
A6: F01 | B6: PDF | C6: PDF·이미지 합치기 | D6: PDF 3개와 사진 2장을 넣고 순서를 바꾼 뒤 [책갈피 넣기]로 실행합니다. | E6: D01, D03, D14 | F6: 목록 순서대로 1개 파일이 되고 쪽수 합계가 맞으며, 책갈피가 파일별로 생깁니다. 회전된 쪽 방향이 유지됩니다. | G6: Y
A7: F02 | B7: PDF | C7: PDF 나누기 | D7: 30쪽 PDF를 10쪽 단위로 나눕니다. | E7: D01 | F7: 3개 파일이 생기고 각 10쪽, 내용 순서가 원본과 같습니다. | G7: Y
A8: F03 | B8: PDF | C8: PDF 페이지 추출 | D8: "1,3,5-7"처럼 페이지를 지정합니다. | E8: D01 | F8: 지정한 5쪽만 순서대로 담깁니다.
A9: F04 | B9: PDF | C9: PDF 순서 바꾸기 | D9: "3,1,2"처럼 순서를 입력합니다. | E9: D01 | F9: 입력한 순서대로 구성됩니다.
A10: F05 | B10: PDF | C10: PDF 페이지 편집(썸네일) | D10: 썸네일을 끌어 순서 변경, 1쪽 회전, 1쪽 삭제, 1쪽 복제 후 저장합니다. 두 번째 PDF의 쪽도 섞어 봅니다. | E10: D01, D03 | F10: 저장된 PDF가 화면에서 편집한 결과와 같습니다. | G10: Y
A11: F06 | B11: PDF | C11: PDF 페이지 회전 | D11: 2쪽을 90도 회전합니다. | E11: D01 | F11: 해당 쪽만 회전되고 내용이 잘리지 않습니다.
A12: F07 | B12: PDF | C12: PDF 쪽번호 넣기 | D12: 가로·회전 쪽이 섞인 PDF에 쪽번호(하단 가운데)를 넣습니다. | E12: D03 | F12: 모든 쪽에서 번호가 보이는 방향 기준 하단 가운데에 있습니다.
A13: F08 | B13: PDF | C13: PDF 텍스트 추출 | D13: 일반 PDF의 글자를 TXT로 저장해 원문과 비교합니다. | E13: D01 | F13: 본문 글자가 빠짐없이 나오고 한글이 깨지지 않습니다. 스캔 PDF는 글자가 없다는 안내가 뜹니다.
A14: F09 | B14: PDF | C14: PDF를 이미지로 | D14: PNG·JPG로 각 1회 변환합니다. | E14: D01 | F14: 쪽 수만큼 이미지가 나오고 글자가 선명합니다.
A15: F10 | B15: PDF | C15: PDF 긴 이미지 | D15: 3쪽을 세로로 이어 붙입니다. | E15: D01 | F15: 한 장의 긴 이미지로 순서대로 붙습니다.
A16: F11 | B16: PDF | C16: PDF 이미지 압축 | D16: 스캔 PDF를 압축합니다. | E16: D02 | F16: 용량이 줄고 내용을 읽을 수 있습니다. 글자 검색이 안 된다는 안내가 있습니다.
A17: F12 | B17: PDF | C17: PDF 목표 용량 압축 | D17: "2MB 이하"로 지정합니다. | E17: D02, D04 | F17: 2MB 이하로 저장되거나, 불가능하면 오류 안내와 함께 원본을 건드리지 않습니다.
A18: F13 | B18: PDF | C18: PDF A4 맞춤 | D18: 크기가 다른 쪽이 섞인 PDF를 A4로 맞춥니다. | E18: D03 | F18: 모든 쪽이 A4이고 내용 비율이 유지되며 잘리지 않습니다.
A19: F14 | B19: PDF | C19: PDF 유인물 만들기 | D19: 4쪽 모아찍기로 만듭니다. | E19: D01 | F19: A4 한 장에 4쪽씩 순서대로 배치됩니다.
A20: F15 | B20: PDF | C20: PDF 빈 페이지 제거 | D20: "완전히 빈 쪽만"으로 실행합니다. | E20: D05 | F20: 빈 쪽만 지워지고 내용 있는 쪽(희미한 쪽 포함)은 남습니다. 지운 쪽 번호 안내가 나옵니다. | G20: Y
A21: 보안 도구
A22: F16 | B22: 보안 | C22: PDF 워터마크 | D22: 부서명·사번·일시 워터마크를 대각선으로 넣습니다. | E22: D01, D03 | F22: 모든 쪽에 보이고 본문을 가리지 않으며 회전 쪽에서도 방향이 맞습니다.
A23: F17 | B23: 보안 | C23: PDF 암호 설정 | D23: 열기 암호와 인쇄 금지를 설정하고 회사 PDF 뷰어로 엽니다. | E23: D01 | F23: 암호를 물어보고, 인쇄가 막힙니다. 4자 미만 암호는 거부됩니다. | G23: Y
A24: F18 | B24: 보안 | C24: PDF 암호 해제 | D24: 아는 암호로 해제합니다. 틀린 암호도 한 번 넣어 봅니다. | E24: D06 | F24: 맞는 암호는 해제된 사본이 생기고, 틀린 암호는 "암호가 맞지 않습니다" 안내가 뜹니다.
A25: F19 | B25: 보안 | C25: PDF 문서정보 지우기 | D25: 파일 속성(작성자·프로그램)이 있는 PDF를 정리하고, 회사 PDF 뷰어의 [문서 속성]으로 확인합니다. | E25: D01 | F25: 작성자·제목·프로그램 정보가 비어 있습니다.
A26: F20 | B26: 보안 | C26: 사진 위치정보 제거 | D26: GPS가 있는 휴대폰 사진을 처리하고 윈도우 [속성 → 자세히]로 확인합니다. | E26: D14 | F26: GPS·촬영 기기 정보가 사라집니다.
A27: F21 | B27: 보안 | C27: 전자서명 PDF 보호 | D27: 전자서명 PDF를 쪽번호 넣기에 넣습니다. | E27: D07 | F27: "전자서명 문서는 가공할 수 없습니다" 안내가 뜨고 결과가 만들어지지 않습니다. | G27: Y
A28: 이미지 도구
A29: F22 | B29: 이미지 | C29: 이미지를 PDF로 | D29: 사진 3장을 A4 PDF로 만듭니다. | E29: D14, D15 | F29: 순서대로 1개 PDF가 되고 사진이 잘리지 않습니다.
A30: F23 | B30: 이미지 | C30: 이미지 포맷 변환 | D30: PNG→JPG, JPG→WebP로 변환합니다. | E30: D15, D16 | F30: 형식이 바뀌고 투명 PNG는 흰 배경으로 바뀝니다.
A31: F24 | B31: 이미지 | C31: 이미지 크기 조절 | D31: 가로 1200px로 줄입니다. | E31: D17 | F31: 가로 1200px, 비율 유지.
A32: F25 | B32: 이미지 | C32: 이미지 용량 맞추기 | D32: "300KB 이하"로 지정합니다. | E32: D17 | F32: 300KB 이하로 저장됩니다.
A33: F26 | B33: 이미지 | C33: 문서용 이미지 최적화 | D33: [게시판] 프리셋으로 처리합니다. | E33: D14, D17 | F33: 게시판 규격 크기·용량으로 일괄 변환됩니다.
A34: F27 | B34: 이미지 | C34: 이미지 회전 | D34: 90도 회전합니다. | E34: D14 | F34: 회전된 방향으로 저장됩니다.
A35: F28 | B35: 이미지 | C35: 이미지 좌우 반전 | D35: 좌우 반전합니다. | E35: D15 | F35: 좌우가 뒤집힙니다.
A36: F29 | B36: 이미지 | C36: 이미지 자르기 | D36: 좌표·크기를 지정해 자릅니다. | E36: D15 | F36: 지정 영역만 남습니다.
A37: F30 | B37: 이미지 | C37: 이미지 흰 여백 제거 | D37: 흰 여백이 있는 캡처를 처리합니다. | E37: D15 | F37: 가장자리 흰 여백만 잘립니다.
A38: F31 | B38: 이미지 | C38: 이미지 밝기와 흑백 | D38: 흑백 + 밝기 조정을 적용합니다. | E38: D14 | F38: 흑백으로 바뀌고 밝기가 반영됩니다.
A39: F32 | B39: 이미지 | C39: 이미지 이어 붙이기 | D39: 4장을 2×2 격자로 붙입니다. | E39: D15 | F39: 한 장에 격자로 배치됩니다.
A40: 문서 내용 추출
A41: F33 | B41: 문서 추출 | C41: Word 글자 추출 | D41: 표가 있는 DOCX를 TXT로 추출해 원문과 대조합니다. | E41: D11 | F41: 본문과 표 글자가 순서대로 빠짐없이 나옵니다.
...

Sheet 3_시험문서
A1: 3. 시험 문서 준비 목록
A2: 모든 문서는 DRM을 해제한 사본이나 비보호 문서만 씁니다(D18 제외). 개인정보가 많은 문서는 가급적 피하고, 쓸 경우 시험 후 바로 지웁니다.
A4: ID | B4: 문서 유형 | C4: 조건·특징 | D4: 최소 수량 | E4: 준비 수량 | F4: 사용 점검 ID | G4: 비고
A5: D01 | B5: 일반 텍스트 PDF | C5: 글자 선택이 되는 10~30쪽 업무 문서(보고서·공문). 표·도장 이미지 포함 문서 3건 이상 | D5: 10 | F5: E04~E14, F01~F19
A6: D02 | B6: 스캔 PDF | C6: 복합기로 스캔해 글자 선택이 안 되는 PDF | D6: 5 | F6: F11, F12, F40
A7: D03 | B7: 가로·세로·회전 쪽 PDF | C7: 가로 쪽과 세로 쪽이 섞였거나 회전된 쪽이 있는 PDF, 쪽 크기가 다른 PDF | D7: 3 | F7: F01, F05, F07, F13, F16
A8: D04 | B8: 대용량 PDF | C8: 100쪽 이상 2건(그중 300쪽 이상 1건), 50MB 이상 1건 포함 권장 | D8: 2 | F8: E19, E22, F12, F44
A9: D05 | B9: 빈 쪽 포함 PDF | C9: 완전 빈 쪽 + 희미한 내용(머리말만 있는 쪽 등)이 섞인 PDF | D9: 3 | F9: F15, F42
A10: D06 | B10: 암호 PDF(암호 아는 것) | C10: 열기 암호가 걸린 PDF와 그 암호 | D10: 2 | F10: F18
A11: D07 | B11: 전자서명 PDF | C11: 전자서명(공동인증서·전자계약)이 들어간 PDF | D11: 2 | F11: F21
A12: D08 | B12: 주석·입력칸 PDF | C12: 메모·형광펜 주석이나 입력 양식이 있는 PDF | D12: 2 | F12: F05, F09
A13: D09 | B13: HWPX 문서 | C13: 한글 2014 이후 형식, 표·그림 포함 | D13: 10 | F13: F35, F38, F39
A14: D10 | B14: HWP 문서(구형) | C14: HWP 5.0 형식, 표 포함. 글상자·각주 있는 문서 2건 이상 | D14: 10 | F14: F36
A15: D11 | B15: Word(DOCX) | C15: 표·그림 포함 | D15: 8 | F15: F33, F38
A16: D12 | B16: PowerPoint(PPTX) | C16: 슬라이드 순서를 여러 번 바꾼 파일 2건 이상, 그림 포함 | D16: 8 | F16: F34, F38
... A28: D24 | B28: 특수 파일명 | C28: 괄호·&·#·긴 한글 이름의 파일 | D28: 5 | F28: E23, F46
B29: 합계 | D29: =SUM(D5:D28) -> 112 | E29: =SUM(E5:E28) -> 0
B30: 준비 완료 유형 수 | E30: =SUMPRODUCT((E5:E28<>"")*(E5:E28>=D5:D28)) -> 0 | F30: / 24개 유형

Sheet 4_오류기록
A1: 4. 오류 기록
A2: 실패·보류 1건당 한 줄. 첫 줄은 작성 예시입니다(덮어써도 됩니다). 캡처 파일명은 오류번호로 저장합니다(예: ER-001.png).
A4: 오류번호 | B4: 점검 ID | C4: 발생일 | D4: 브라우저 | E4: PC 구분 | F4: 문서 특징(원본 첨부 금지) | G4: 증상(화면 문구 그대로) | H4: 재현 여부 | I4: 캡처 파일명 | J4: 조치 결과
A5: ER-001 | B5: F36 | C5: 2026-10-27 | D5: Edge | E5: 일반 사무용 | F5: HWP 5.0, 12쪽, 글상자 3개, 한글 2010 작성 | G5: 추출 TXT에 글상자 안 문장이 빠짐(본문·표는 정상) | H5: 항상 | I5: ER-001.png
